Workbook

Sheet RESUMO DO PROJETO
A1: RESUMO DO PROJETO — pra outro Claude/chat continuar de onde parei
A3: Esse resumo existe porque essa conversa já passou de 1 semana e o usuário (Rod) bateu limite de anexo no chat atual. O objetivo é: quem ler isso (outro Claude, em outro chat) deve conseguir continuar o trabalho com ~90% do contexto que o Claude anterior tinha. Leia isso INTEIRO antes de mexer em qualquer coisa. Depois, sempre CONFIRME contra o código/planilha real antes de assumir que algo funciona — esse projeto tem um histórico forte de "achei que funcionava, mas não funcionava" (ver seção de Armadilhas).
A5: 1. O QUE É O JOGO
A6: RPG solo em Telegram, bot chamado "Zeyrith RPG" (ou nome similar no BotFather), tema "A Infecção que Segura o Mundo" — pós-apocalíptico de fantasia, uma corrupção/Infecção Carmesim que espalhou pelo continente. 14 Tiers de progressão (Sucata Enferrujada → Estelar/Cósmico), 5 Atos narrativos, 7 Polos/Reinos, 8 Classes jogáveis. É PVE solo — qualquer pessoa que mandar /start pro bot ganha personagem próprio e isolado (não é preciso nenhum trabalho extra pra "multiplayer casual" nesse sentido — cada telegram_id é um personagem separado). Multiplayer/cooperativo de verdade (Fase 7) foi DECIDIDO e ADIADO, não é bug nem esquecimento.
A8: 2. ARQUITETURA — MUITO IMPORTANTE ENTENDER ISSO PRIMEIRO
A9: A PLANILHA é a fonte de verdade de todo dado de jogo (monstro, item, missão, local, etc). O BOT (Python/Telegram) só lê esse dado, nunca inventa. O fluxo é sempre o mesmo, nessa ordem: 1) Editar a planilha balanceamento_rpg-13.xlsx (ou -13-31.xlsx, os nomes variaram ao longo da conversa, sempre confirme qual está sendo usado). 2) Rodar `python3 db/export_json.py` — isso abre a planilha com LibreOffice headless (`soffice --headless --calc --convert-to xlsx`) pra RECALCULAR fórmulas antes de ler os valores (openpyxl sozinho não recalcula fórmula), e escreve `data/game_data.json`. 3) Rodar a importação (`from db.import_data import importar; importar()`) — isso lê o JSON e escreve no banco (SQLite local pra teste, Postgres/Neon em produção via Render). 4) SEMPRE testar o handler de verdade depois (chamando a função async com mocks), nunca assumir que "deve funcionar" só porque o dado foi importado. Pra achar erro de fórmula na planilha (tipo #REF!, #N/A), sempre recalcular com LibreOffice headless e contar erros — o número de baseline validado é 10 erros conhecidos (FILTER() incompatível com LibreOffice, funciona no Google Sheets, não é bug real).
A11: 3. ARMADILHAS CONHECIDAS — LEIA ISSO OU VAI PERDER TEMPO REPETINDO ERRO
A12: ⚠️ ACENTO: a mesma informação (nome de Tier, nome de tipo de arma, etc) às vezes aparece COM acento numa aba da planilha e SEM acento em outra. Ex: Tier.nome usa sempre SEM acento ("Aco Elfico", "Ferro Orquico", "Ebano") em TODO o sistema (Bestiário, Missões, Locais), mas outras abas (Crafting-Receitas, Recursos Naturais) às vezes trazem o nome COM acento ou em formato diferente ("Tier 8 (Ferro Órquico)", "Tier 1" numérico puro). Isso já causou pelo menos 4 bugs reais diferentes nessa conversa. Sempre que ligar duas tabelas pelo nome de Tier/tipo, ou normalize os dois lados (tem uma função `_normalizar()` em game/economia.py que remove acento) ou confirme os valores reais direto no banco antes de assumir que o JOIN vai bater.
A14: ⚠️ TELEGRAM SÓ ACEITA 1 RESPOSTA POR CLIQUE (callback_query.answer()): se o código chama `await query.answer()` (vazio) e DEPOIS chama `await query.answer("mensagem", show_alert=True)` no mesmo fluxo (sem branch/return entre elas), a SEGUNDA chamada é silenciosamente ignorada pelo Telegram. Esse bug apareceu em 11 funções diferentes numa única varredura. O padrão correto é: só chamar answer() UMA VEZ por execução, e se tem caminho de erro vs sucesso, cada um deve ter sua PRÓPRIA chamada de answer() (nunca as duas no mesmo caminho).
A16: ⚠️ REAPROVEITAR query.data: vários handlers terminam chamando outro handler pra "atualizar a tela" (ex: `confirmar_compra` chama `listar_compra` no final). Se o handler chamado espera fazer `query.data.split("_")` num formato diferente do que originou a ação, ele lê o ID errado como se fosse outra coisa (ex: um ID de compra virando "tipo" de categoria por engano). Sempre que isso acontecer, sobrescreva `query.data` manualmente pro formato certo ANTES de chamar o outro handler.
A18: ⚠️ SESSÃO DO SQLALCHEMY: nunca acesse atributo de objeto do banco (`objeto.campo`) depois de `session.close()`. Sempre extraia pra variável Python simples ANTES de fechar a sessão. Já causou bug real mais de uma vez.
A20: ⚠️ Armadura usa coluna `slot`, Arma usa coluna `tipo` — são nomes diferentes pro "mesmo conceito" (Espada/Peitoral/etc). Fácil esquecer e tentar `.tipo` numa Armadura (dá AttributeError).
... A46: Rod não programa — trabalha só pela planilha + conversa aqui. Esse é o CHECKLIST de como toda resposta deve funcionar, não é opcional, é o que ele mais valoriza no processo: 1) SEMPRE testar de verdade (rodar o handler com mock/sessão real) antes de dizer que algo funciona. Nunca assumir só de ler o código. 2) Quando for mudar uma tela/fluxo, editar a PLANILHA e o PYTHON juntos, na mesma resposta. 3) Depois de qualquer mudança visual, mostrar um MOCKUP com o TEXTO REAL que saiu do teste — nunca um mockup inventado/imaginado. 4) Mostrar esse mockup sempre NO FINAL da resposta, não no meio. 5) Se aparecer algo estranho no caminho que não foi pedido, investigar e resolver também, avisando que foi achado no caminho. 6) Não reenviar os arquivos toda hora — só quando ele pedir ou quando terminar um bloco grande de mudanças. 7) Em decisão de design (não bug), propor número/desenho concreto pra aprovar, em vez de pergunta aberta. Esse fluxo (testar → achar bug real → consertar planilha+python → testar de novo → mockup com dado real → aprovação → próximo item) é a espinha dorsal de como essa conversa toda funcionou por mais de uma semana. Seguir isso é mais importante que qualquer feature individual.

Sheet Indice Geral
A1: A Infecção que Segura o Mundo — Índice Geral (fechado 28/08)
A2: Todas as mecânicas, blocos fechados, e onde achar cada coisa. Comece aqui se estiver perdido.
A4: Sistema | B4: Onde está | C4: Status
A5: Progressão de Nível/Dano/Defesa | B5: Curva Mestra, Tiers | C5: ✅ Fechado
A6: Bestiário (123 monstros) | B6: Bestiario | C6: ✅ Fechado — efeitos, fraqueza, materiais
A7: Armas (308) / Armaduras (252) | B7: Armas, Armaduras | C7: ✅ Fechado — Variação, Mod.Variação, Preço
A8: Lendários/Artefatos (79) | B8: Artefatos e Relíquias | C8: ✅ Fechado — Dano/Defesa Base, flag Combate
A9: Missões (115+) | B9: Missoes | C9: ✅ Fechado — Facção/Reputação nas 13 principais
A10: Crafting (210 receitas) | B10: Crafting - Receitas | C10: ✅ Fechado — 4 níveis de fricção
A11: Materiais (157) | B11: Recursos Naturais | C11: ✅ Fechado — identidade visual, troféus
A12: Economia/Preço | B12: Economia, Cidades e NPCs | C12: ✅ Fechado — fórmula única
A13: Perigo/Atenção/Exploração | B13: Mundo - Locais, Regras e Fórmulas | C13: ✅ Fechado
A14: Descanso/Marcos de Nível | B14: Regras e Fórmulas | C14: ✅ Fechado
A15: Facções/Relação com NPC | B15: Reinos e Facções, Regras e Fórmulas | C15: ✅ Fechado
... A29: Bestiário Expandido (Tier 1 piloto) | B29: Bestiario, Monstros Raros | C29: ✅ Tier 1: 8→28 monstros. Meta final: ~400-470 nos 14 tiers. Tiers 2-14 pendentes.
A30: PENDENTE: Backfill de Papel de Combate + Condição de Spawn nos ~115 monstros originais (pre-existentes) dos Tiers 2-14. Fazer depois que a expansao completa (Tiers 1-14) terminar.
A31: PENDENTE (em espera, aguardando decisao): sistema de 10-15 missoes por Tier com bloqueio por Honra/Reputacao (Comum/Veterano/Lendario), 6 categorias por Tier (Principal/Caca/Coleta/Elite/Social/Exploracao). Hoje so existe 1 Principal por tier + pouquissimas secundarias (Tier1 tem so 2). Precisa de decisao antes de expandir.
A32: RESOLVIDO 03/09: Mundo-Locais reconciliada com o Bestiario. 32 locais formais, cobrindo todos os 29 nomes que os 470 monstros referenciam (1 excecao legitima: referencia dupla Estrada/Acampamento, ambos ja existentes).

Sheet Codex
A1: Codex — tudo que o jogador aprende e fica salvo pra sempre (estilo Crimson Desert)
A2: Isso é o TEMPLATE de estrutura pro app (Telegram Mini App) — o estado real de cada jogador (o que ele já descobriu) mora no banco de dados do app, não aqui. Essa aba mostra O QUE existe pra ser descoberto.
A4: Categoria do Codex | B4: Fonte (aba da planilha) | C4: Quantidade total | D4: Como é aprendido | E4: Fica salvo como
A5: Receitas Aprendidas | B5: Crafting - Receitas | C5: 210 receitas-base + variantes Nível 2-4 | D5: Ler 1x a Receita física (consumida no uso) | E5: Permanente — nunca mais precisa comprar de novo
A6: Bestiário (Knowledge) | B6: Bestiario | C6: 470 criaturas, 0-5 de Knowledge cada | D6: Observar / combater / estudar cadáver / NPC / livro | E6: Nível de Knowledge fica salvo, nunca regride
A7: Materiais Identificados | B7: Recursos Naturais | C7: 600 materiais | D7: Teste INT/SAB, NPC especialista, ou quest | E7: Uma vez identificado, sempre reconhecido
A8: NPCs (Relação) | B8: Cidades e NPCs (35 nomeados) | C8: 35 NPCs | D8: Ações (não presente) — sobe por consequência real | E8: Nível de relação fica salvo, inclusive traição
A9: Facções (Reputação) | B9: Reinos e Facções | C9: 7 facções | D9: Escolhas de quest (221 já mapeadas) | E9: -100 a +100, permanente
A10: Locais Descobertos | B10: Mundo - Locais | C10: 53 locais | D10: Explorar/chegar no local pela primeira vez | E10: Mapa revela permanentemente
A11: Títulos Conquistados | B11: Titulos | C11: 17 títulos (mais podem ser criados) | D11: Cumprir a condição (Proficiência 100, Bestiário, Reputação etc.) | E11: Exibido no personagem pra sempre
A12: Lendários/Artefatos Encontrados | B12: Artefatos e Relíquias | C12: 93 itens únicos | D12: Loot ou recompensa de quest | E12: Registrado mesmo se vendido/perdido depois
A13: Lore/Fragmentos do Aspecto | B13: Fragmentos do Aspecto | C13: 5 fragmentos (1 por Ato) | D13: Derrotar o boss que carrega cada um | E13: Progresso da história principal, visível no Codex
A14: Ferramentas de Coleta | B14: Crafting - Receitas | C14: 84 (14 tiers x 3 ferramentas x Padrão/Refinada) | D14: Comprar Receita + craftar na Forja | E14: Permanente, mostra no Codex de Ferramentas
A15: Comida/Bebida | B15: Crafting - Receitas | C15: 14 (1 por tier) | D15: Comprar Receita + craftar em qualquer Fogueira | E15: Buff temporário, receita fica permanente
... A17: Consumíveis (Poção, Antídoto, Veneno) | B17: Consumiveis | C17: 56 (4x14) + 14 Viais de Veneno = 70 | D17: Comprar ou craftar | E17: Não é permanente — item consumível, cada um se gasta ao usar

Sheet Regras e Fórmulas
A1: REGRAS DE MESA — cola rápida (motor completo está nas abas Curva Mestra / Armas / Armaduras / Bestiario)
A3: 1. Resolução de ataque
A4: d20 + Bônus de Ataque(atacante) >= Defesa(alvo) -> acerta
A5: Regra de dado: natural 1 = sempre erra<br>natural 20 = sempre acerta
A6: Chance de acerto = (21 - (Defesa alvo - seu Bônus Ataque)) / 20, entre 5% e 95%
A8: 2. Dano
A9: Dano = ARREDONDA(DanoBaseTier(Tier,Raridade) x ModTipo x ModVariação, 0) — ver detalhe completo na Seção 8
A10: Adaga x0,8 (ver Seção 8: 25% chance de golpe extra a 50% do dano — NÃO é 2 ataques garantidos)<br>Espada x1,0<br>Machado x1,2<br>Maça x1,1
A11: Arco x0,9 (sempre 2 mãos)<br>Manopla x0,85 (sem golpe extra — Atordoamento é a identidade dela)<br>Cetro x0,7
A14: 3. Defesa
A15: Defesa = soma dos 8 slots equipados + mod. DES
A16: Peso de cada slot no orçamento de Defesa do tier:
... A159: Colunas novas em Missoes: Categoria, Requisito_Honra, Requisito_Nivel, Requisito_Quest_Previa, Requisito_Faccao, Requisito_Condicao_Texto, Recompensa_Item.

Sheet Motor do Mestre
A1: Motor do Mestre — gera encontro, loot, quests e cidade em 1 clique
A2: Mude o Tier abaixo e edite a célula (ou F9) pra sortear de novo.
A4: TIER DO GRUPO: | B4: Sucata Enferrujada
A6: 1. ENCONTRO SORTEADO
A7: Rolagem de Papel (d100) | B7: =RANDBETWEEN(1,100)
A8: Papel sorteado (55% Comum / 30% Elite / 15% Boss) | B8: =ifs($B$7<=55,"Comum",$B$7<=85,"Elite",TRUE(),"Boss")
A9: Monstro sorteado | B9: =INDEX(filter(Bestiario!$B$12:$B$700,Bestiario!$A$12:$A$700=$B$4,Bestiario!$C$12:$C$700=$B$8),RANDBETWEEN(1,COUNTIFS(Bestiario!$A$12:$A$700,$B$4,Bestiario!$C$12:$C$700,$B$8)))
A10: Nível | B10: =IFERROR(INDEX(Bestiario!$D$12:$D$700,MATCH($B$9,Bestiario!$B$12:$B$700,0)),"")
A11: HP | B11: =IFERROR(INDEX(Bestiario!$E$12:$E$700,MATCH($B$9,Bestiario!$B$12:$B$700,0)),"")
A12: Dano | B12: =IFERROR(INDEX(Bestiario!$F$12:$F$700,MATCH($B$9,Bestiario!$B$12:$B$700,0)),"")
A13: Defesa | B13: =IFERROR(INDEX(Bestiario!$G$12:$G$700,MATCH($B$9,Bestiario!$B$12:$B$700,0)),"")
A14: Golpe Especial | B14: =IFERROR(INDEX(Bestiario!$I$12:$I$700,MATCH($B$9,Bestiario!$B$12:$B$700,0)),"")
A15: Efeito do Golpe | B15: =IFERROR(INDEX(Bestiario!$J$12:$J$700,MATCH($B$9,Bestiario!$B$12:$B$700,0)),"")
A17: 2. LOOT SORTEADO
A18: Tipo de Arma | B18: =INDEX(Armas!$A$5:$A$11,RANDBETWEEN(1,7))
A19: Rolagem de Raridade (d100) | B19: =RANDBETWEEN(1,100)
A20: Raridade (60% Comum / 30% Raro / 10% Lendário) | B20: =ifs($B$19<=60,"Comum",$B$19<=90,"Raro",TRUE(),"Lendario")
A21: Nº do Tier atual (auxiliar) | B21: =MATCH($B$4,Tiers!$B$9:$B$22,0)
A22: Variação sorteada (se Comum/Raro) | B22: =IF($B$20="Lendario","(ver linha de Lendário abaixo)",INDEX(filter(Armas!$C$15:$C$322,Armas!$A$15:$A$322=$B$4,Armas!$B$15:$B$322=$B$18),RANDBETWEEN(1,COUNTIFS(Armas!$A$15:$A$322,$B$4,Armas!$B$15:$B$322,$B$18))))
A23: Dano do item (Comum ou Raro) | B23: =IFERROR(IF($B$20="Comum",INDEX(Armas!$I$15:$I$322,MATCH($B$22,Armas!$C$15:$C$322,0)),IF($B$20="Raro",INDEX(Armas!$J$15:$J$322,MATCH($B$22,Armas!$C$15:$C$322,0)),"")),"")
A24: Efeito Especial do item | B24: =IFERROR(INDEX(Armas!$D$15:$D$322,MATCH($B$22,Armas!$C$15:$C$322,0)),"")
A25: Lendário sorteado (se Lendario) | B25: =IF($B$20<>"Lendario","",IFERROR(INDEX(filter('Artefatos e Relíquias'!$C$5:$C$90,'Artefatos e Relíquias'!$L$5:$L$90="Lendário",LEFT('Artefatos e Relíquias'!$D$5:$D$90,4)="Arma",ISNUMBER(SEARCH("Tier "&$B$21&" ",'Artefatos e Relíquias'!$E$5:$E$90))),RANDBETWEEN(1,COUNTIFS('Artefatos e Relíquias'!$L$5:$L$90,"Lendário",'Artefatos e Relíquias'!$D$5:$D$90,"Arma*",'Artefatos e Relíquias'!$E$5:$E$90,"*Tier "&$B$21&" *"))),"(nenhum Lendário de arma cadastrado nesse tier)"))
A26: Descrição final | B26: =IF($B$20="Lendario","1 "&$B$25,"1 "&$B$18&" — "&$B$22&" ("&$B$20&") — Dano "&$B$23&IF($B$24<>"",", Efeito: "&$B$24,""))
A30: 3. MISSÕES DISPONÍVEIS NESTE TIER
A31: Nome | B31: Tipo | C31: Objetivo | D31: Recompensa
A32: =IFERROR(filter(Missoes!$B$16:$E$400,Missoes!$A$16:$A$400=$B$4),"(nenhuma cadastrada)")
A67: LOCAL ATUAL (pra Perigo): | B67: Vila Inicial
A68: Perigo do Local (1-5) | B68: =IFERROR(INDEX('Mundo - Locais'!$L$5:$L$130,MATCH($B$67,'Mundo - Locais'!$A$5:$A$130,0)),3)
A69: 4. CIDADE / MERCADOR DA REGIÃO
A70: Cidade | B70: Teto de Tier p/ Venda | C70: Custo de Descanso (Ouro) | D70: Descrição
A71: =IFERROR(filter('Cidades e NPCs'!$A$20:$A$26,ISNUMBER(SEARCH($B$4,'Cidades e NPCs'!$B$20:$B$26))),"") | B71: =IFERROR(filter('Cidades e NPCs'!$F$20:$F$26,ISNUMBER(SEARCH($B$4,'Cidades e NPCs'!$B$20:$B$26))),"") | C71: =IFERROR(filter('Cidades e NPCs'!$G$20:$G$26,ISNUMBER(SEARCH($B$4,'Cidades e NPCs'!$B$20:$B$26))),"") | D71: =IFERROR(filter('Cidades e NPCs'!$E$20:$E$26,ISNUMBER(SEARCH($B$4,'Cidades e NPCs'!$B$20:$B$26))),"")
A73: 5. ENCONTRO ALEATÓRIO DE EXPLORAÇÃO (1d100) | D73: Perigo | E73: Nada até | F73: Comum até | G73: Elite até | H73: AmeaçaSup até | I73: Boss até
A74: Rolagem (1d100) | B74: =RANDBETWEEN(1,100) | D74: 1 | E74: 70 | F74: 90 | G74: 97 | H74: 99 | I74: 99
A75: Resultado (tabela de Perigo do local selecionado) | B75: =ifs($B$74<=INDEX($E$74:$E$78,MATCH($B$68,$D$74:$D$78,0)),"Nada acontece",$B$74<=INDEX($F$74:$F$78,MATCH($B$68,$D$74:$D$78,0)),"Monstro Comum do tier atual",$B$74<=INDEX($G$74:$G$78,MATCH($B$68,$D$74:$D$78,0)),"Monstro Elite do tier atual",$B$74<=INDEX($H$74:$H$78,MATCH($B$68,$D$74:$D$78,0)),"Ameaça Superior (próximo tier)",$B$74<=INDEX($I$74:$I$78,MATCH($B$68,$D$74:$D$78,0)),"Emboscada de Boss do tier atual",TRUE(),"Achado raro (loot sem combate)") | D75: 2 | E75: 60 | F75: 83 | G75: 94 | H75: 98 | I75: 99
A76: Tier a usar no sorteio | B76: =IF($B$75="Ameaça Superior (próximo tier)",IFERROR(INDEX(Tiers!$B$9:$B$22,MATCH($B$4,Tiers!$B$9:$B$22,0)+1),"(já é o último tier)"),$B$4) | D76: 3 | E76: 50 | F76: 75 | G76: 87 | H76: 95 | I76: 99
A77: Papel a sortear | B77: =ifs($B$75="Monstro Comum do tier atual","Comum",$B$75="Monstro Elite do tier atual","Elite",$B$75="Ameaça Superior (próximo tier)","Elite",$B$75="Emboscada de Boss do tier atual","Boss",TRUE(),"") | D77: 4 | E77: 35 | F77: 63 | G77: 80 | H77: 93 | I77: 99
A78: Monstro sorteado (se aplicável) | B78: =IF($B$77="","— (sem combate neste resultado)",INDEX(filter(Bestiario!$B$12:$B$718,Bestiario!$A$12:$A$718=$B$76,Bestiario!$C$12:$C$718=$B$77),RANDBETWEEN(1,COUNTIFS(Bestiario!$A$12:$A$718,$B$76,Bestiario!$C$12:$C$718,$B$77)))) | D78: 5 | E78: 20 | F78: 45 | G78: 65 | H78: 85 | I78: 97

Sheet Curva Mestra
A1: Curva Mestra de Progressão
A2: Parametros em azul podem ser ajustados - tudo abaixo recalcula automaticamente.
A4: Parametro | B4: Valor | C4: O que controla | K4: Parametro XP | L4: Valor | N4: Parametro Mana | O4: Valor
A5: HP_base | B5: 18 | C5: HP inicial no nivel 1 (parte fixa) | K5: XP_base | L5: 50 | N5: Mana_base | O5: 10
A6: HP_lin | B6: 6 | C6: Crescimento linear de HP por nivel | K6: XP_lin | L6: 20 | N6: Mana_lin | O6: 4
A7: HP_quad | B7: 0.35 | C7: Crescimento acelerado de HP (nivel ao quadrado) | K7: XP_quad | L7: 3 | N7: Mana_quad | O7: 0.5
A8: Mult_MonstroComum | B8: 0.5 | C8: HP do monstro comum = HP jogador x este valor
A9: Mult_MonstroElite | B9: 1.2 | C9: HP do monstro elite = HP jogador x este valor
A10: Mult_MonstroBoss | B10: 1.35 | C10: HP do boss = HP jogador x este valor
A11: Mult_MonstroCosmico | B11: 2.2 | C11: HP de entidade cosmica = HP jogador x este valor
A12: Divisor_DanoArma | B12: 5 | C12: Dano de arma padrao = HP monstro comum / este valor
A13: Defesa_base | B13: 5 | C13: Defesa esperada no nivel 1
A14: Defesa_lin | B14: 0.9 | C14: Crescimento de Defesa por nivel
A15: AtqBonus_base | B15: 2 | C15: Bonus de ataque no nivel 1
A16: AtqBonus_lin | B16: 0.9 | C16: Crescimento do bonus de ataque por nivel
A18: Tabela por Nivel (1 a 75)
A19: Nivel | B19: HP Jogador | C19: Dano Arma Padrao (comum) | D19: Defesa Esperada | E19: Bonus de Ataque | F19: HP Monstro Comum | G19: HP Monstro Elite | H19: HP Monstro Boss | I19: HP Entidade Cosmica | J19: XP p/ Prox. Nivel | M19: Mana Jogador
A20: 1 | B20: =ROUND($B$5+$B$6*A20+$B$7*A20^2,0) | C20: =ROUND(F20/$B$12,0) | D20: =ROUND($B$13+$B$14*A20,0) | E20: =ROUND($B$15+$B$16*A20,0) | F20: =ROUND(B20*$B$8,0) | G20: =ROUND(B20*$B$9,0) | H20: =ROUND(B20*$B$10,0) | I20: =ROUND(B20*$B$11,0) | J20: =ROUND($L$5+$L$6*A20+$L$7*A20^2,0) | M20: =ROUND($O$5+$O$6*A20+$O$7*A20^2,0)
A21: 2 | B21: =ROUND($B$5+$B$6*A21+$B$7*A21^2,0) | C21: =ROUND(F21/$B$12,0) | D21: =ROUND($B$13+$B$14*A21,0) | E21: =ROUND($B$15+$B$16*A21,0) | F21: =ROUND(B21*$B$8,0) | G21: =ROUND(B21*$B$9,0) | H21: =ROUND(B21*$B$10,0) | I21: =ROUND(B21*$B$11,0) | J21: =ROUND($L$5+$L$6*A21+$L$7*A21^2,0) | M21: =ROUND($O$5+$O$6*A21+$O$7*A21^2,0)
A22: 3 | B22: =ROUND($B$5+$B$6*A22+$B$7*A22^2,0) | C22: =ROUND(F22/$B$12,0) | D22: =ROUND($B$13+$B$14*A22,0) | E22: =ROUND($B$15+$B$16*A22,0) | F22: =ROUND(B22*$B$8,0) | G22: =ROUND(B22*$B$9,0) | H22: =ROUND(B22*$B$10,0) | I22: =ROUND(B22*$B$11,0) | J22: =ROUND($L$5+$L$6*A22+$L$7*A22^2,0) | M22: =ROUND($O$5+$O$6*A22+$O$7*A22^2,0)
A23: 4 | B23: =ROUND($B$5+$B$6*A23+$B$7*A23^2,0) | C23: =ROUND(F23/$B$12,0) | D23: =ROUND($B$13+$B$14*A23,0) | E23: =ROUND($B$15+$B$16*A23,0) | F23: =ROUND(B23*$B$8,0) | G23: =ROUND(B23*$B$9,0) | H23: =ROUND(B23*$B$10,0) | I23: =ROUND(B23*$B$11,0) | J23: =ROUND($L$5+$L$6*A23+$L$7*A23^2,0) | M23: =ROUND($O$5+$O$6*A23+$O$7*A23^2,0)
A24: 5 | B24: =ROUND($B$5+$B$6*A24+$B$7*A24^2,0) | C24: =ROUND(F24/$B$12,0) | D24: =ROUND($B$13+$B$14*A24,0) | E24: =ROUND($B$15+$B$16*A24,0) | F24: =ROUND(B24*$B$8,0) | G24: =ROUND(B24*$B$9,0) | H24: =ROUND(B24*$B$10,0) | I24: =ROUND(B24*$B$11,0) | J24: =ROUND($L$5+$L$6*A24+$L$7*A24^2,0) | M24: =ROUND($O$5+$O$6*A24+$O$7*A24^2,0)
A25: 6 | B25: =ROUND($B$5+$B$6*A25+$B$7*A25^2,0) | C25: =ROUND(F25/$B$12,0) | D25: =ROUND($B$13+$B$14*A25,0) | E25: =ROUND($B$15+$B$16*A25,0) | F25: =ROUND(B25*$B$8,0) | G25: =ROUND(B25*$B$9,0) | H25: =ROUND(B25*$B$10,0) | I25: =ROUND(B25*$B$11,0) | J25: =ROUND($L$5+$L$6*A25+$L$7*A25^2,0) | M25: =ROUND($O$5+$O$6*A25+$O$7*A25^2,0)
A26: 7 | B26: =ROUND($B$5+$B$6*A26+$B$7*A26^2,0) | C26: =ROUND(F26/$B$12,0) | D26: =ROUND($B$13+$B$14*A26,0) | E26: =ROUND($B$15+$B$16*A26,0) | F26: =ROUND(B26*$B$8,0) | G26: =ROUND(B26*$B$9,0) | H26: =ROUND(B26*$B$10,0) | I26: =ROUND(B26*$B$11,0) | J26: =ROUND($L$5+$L$6*A26+$L$7*A26^2,0) | M26: =ROUND($O$5+$O$6*A26+$O$7*A26^2,0)
A27: 8 | B27: =ROUND($B$5+$B$6*A27+$B$7*A27^2,0) | C27: =ROUND(F27/$B$12,0) | D27: =ROUND($B$13+$B$14*A27,0) | E27: =ROUND($B$15+$B$16*A27,0) | F27: =ROUND(B27*$B$8,0) | G27: =ROUND(B27*$B$9,0) | H27: =ROUND(B27*$B$10,0) | I27: =ROUND(B27*$B$11,0) | J27: =ROUND($L$5+$L$6*A27+$L$7*A27^2,0) | M27: =ROUND($O$5+$O$6*A27+$O$7*A27^2,0)
A28: 9 | B28: =ROUND($B$5+$B$6*A28+$B$7*A28^2,0) | C28: =ROUND(F28/$B$12,0) | D28: =ROUND($B$13+$B$14*A28,0) | E28: =ROUND($B$15+$B$16*A28,0) | F28: =ROUND(B28*$B$8,0) | G28: =ROUND(B28*$B$9,0) | H28: =ROUND(B28*$B$10,0) | I28: =ROUND(B28*$B$11,0) | J28: =ROUND($L$5+$L$6*A28+$L$7*A28^2,0) | M28: =ROUND($O$5+$O$6*A28+$O$7*A28^2,0)
A29: 10 | B29: =ROUND($B$5+$B$6*A29+$B$7*A29^2,0) | C29: =ROUND(F29/$B$12,0) | D29: =ROUND($B$13+$B$14*A29,0) | E29: =ROUND($B$15+$B$16*A29,0) | F29: =ROUND(B29*$B$8,0) | G29: =ROUND(B29*$B$9,0) | H29: =ROUND(B29*$B$10,0) | I29: =ROUND(B29*$B$11,0) | J29: =ROUND($L$5+$L$6*A29+$L$7*A29^2,0) | M29: =ROUND($O$5+$O$6*A29+$O$7*A29^2,0)
A30: 11 | B30: =ROUND($B$5+$B$6*A30+$B$7*A30^2,0) | C30: =ROUND(F30/$B$12,0) | D30: =ROUND($B$13+$B$14*A30,0) | E30: =ROUND($B$15+$B$16*A30,0) | F30: =ROUND(B30*$B$8,0) | G30: =ROUND(B30*$B$9,0) | H30: =ROUND(B30*$B$10,0) | I30: =ROUND(B30*$B$11,0) | J30: =ROUND($L$5+$L$6*A30+$L$7*A30^2,0) | M30: =ROUND($O$5+$O$6*A30+$O$7*A30^2,0)
A31: 12 | B31: =ROUND($B$5+$B$6*A31+$B$7*A31^2,0) | C31: =ROUND(F31/$B$12,0) | D31: =ROUND($B$13+$B$14*A31,0) | E31: =ROUND($B$15+$B$16*A31,0) | F31: =ROUND(B31*$B$8,0) | G31: =ROUND(B31*$B$9,0) | H31: =ROUND(B31*$B$10,0) | I31: =ROUND(B31*$B$11,0) | J31: =ROUND($L$5+$L$6*A31+$L$7*A31^2,0) | M31: =ROUND($O$5+$O$6*A31+$O$7*A31^2,0)
... A94: 75 | B94: =ROUND($B$5+$B$6*A94+$B$7*A94^2,0) | C94: =ROUND(F94/$B$12,0) | D94: =ROUND($B$13+$B$14*A94,0) | E94: =ROUND($B$15+$B$16*A94,0) | F94: =ROUND(B94*$B$8,0) | G94: =ROUND(B94*$B$9,0) | H94: =ROUND(B94*$B$10,0) | I94: =ROUND(B94*$B$11,0) | J94: =ROUND($L$5+$L$6*A94+$L$7*A94^2,0) | M94: =ROUND($O$5+$O$6*A94+$O$7*A94^2,0)
A97: Modificador de Atributo (regra universal)
A98: Modificador = FLOOR((Atributo-10)/2). Atributo 10 = modificador 0 (bate com a Curva Mestra padrao).
A99: - FOR (Forca): soma no Bonus de Ataque corpo-a-corpo (Espada, Adaga, Machado, Maca, Manopla).
A100: - DES (Destreza): soma no Bonus de Ataque a distancia (Arco) e em rolagens de Fuga.
A101: - CON (Constituicao): soma HP extra = Modificador de CON x Nivel do personagem.
A102: - INT (Inteligencia): soma no dano de Habilidades/Magia (ver aba Magia e Habilidades).
A103: - SAB (Sabedoria): soma em rolagens de Percepcao (ler perigo antes de um combate).
A104: - CAR (Carisma): reduz preco de compra em lojas em 2% por ponto de modificador.
A105: Atributo | B105: Modificador
A106: 1 | B106: =INT((A106-10)/2)
...

Sheet Tiers
A1: Tabela de Tiers de Equipamento
A2: Dano calculado automaticamente a partir da Curva Mestra, no nivel medio do tier.
A4: Multiplicador Raro | B4: 1.15
A5: Multiplicador Lendario | B5: 1.3
A8: # | B8: Tier | C8: Nivel Min | D8: Nivel Max | E8: Nivel Ref. | F8: Cor (hex) | G8: Dano Comum | H8: Dano Raro | I8: Dano Lendario | J8: Local de Obtenção | K8: Historia do Material | L8: Habilidade Lendaria (so na versao Lendario)
A9: 1 | B9: Sucata Enferrujada | C9: 1 | D9: 5 | E9: =ROUND((C9+D9)/2,0) | F9: #8B4A2B | G9: =ROUND(INDEX('Curva Mestra'!$C$20:$C$94,MATCH(E9,'Curva Mestra'!$A$20:$A$94,0)),0) | H9: =ROUND(G9*$B$4,0) | I9: =ROUND(G9*$B$5,0) | J9: Estrada dos Bandidos (loot de bandidos) — encontrado livremente, sem requisito | K9: Ferro velho demais ate pra derreter de novo - mas ainda corta, e e o que se tem. | L9: Sem propriedade especial - resistente o bastante pra nao quebrar facil.
A10: 2 | B10: Bronze | C10: 6 | D10: 10 | E10: =ROUND((C10+D10)/2,0) | F10: #B5651D | G10: =ROUND(INDEX('Curva Mestra'!$C$20:$C$94,MATCH(E10,'Curva Mestra'!$A$20:$A$94,0)),0) | H10: =ROUND(G10*$B$4,0) | I10: =ROUND(G10*$B$5,0) | J10: Mina de Bronze (Valória) | K10: As primeiras minas da regiao. Ninguem lembra quem cavou primeiro - so quem nunca saiu. | L10: Reduz o custo de descanso na estalagem em 10%.
A11: 3 | B11: Ferro | C11: 11 | D11: 15 | E11: =ROUND((C11+D11)/2,0) | F11: #6E7378 | G11: =ROUND(INDEX('Curva Mestra'!$C$20:$C$94,MATCH(E11,'Curva Mestra'!$A$20:$A$94,0)),0) | H11: =ROUND(G11*$B$4,0) | I11: =ROUND(G11*$B$5,0) | J11: Ruínas da Antiga Forja (Cinzenta) — requer forja construída (primeiro marco de crafting) | K11: Forjado as pressas quando bandidos deixaram de ser o unico perigo na estrada. | L11: +1 de Ataque adicional (fabricacao confiavel).
A12: 4 | B12: Prata | C12: 16 | D12: 20 | E12: =ROUND((C12+D12)/2,0) | F12: #C7C7CC | G12: =ROUND(INDEX('Curva Mestra'!$C$20:$C$94,MATCH(E12,'Curva Mestra'!$A$20:$A$94,0)),0) | H12: =ROUND(G12*$B$4,0) | I12: =ROUND(G12*$B$5,0) | J12: Criptas de Prata (Cinzenta) — minerado em meio a mortos-vivos (bônus vs. undead) | K12: Prateado o bastante pra brilhar na escuridao das criptas - o que atrai tanto quanto afasta. | L12: +50% de dano contra mortos-vivos.
A13: 5 | B13: Aco Elfico | C13: 21 | D13: 25 | E13: =ROUND((C13+D13)/2,0) | F13: #7A8B4A | G13: =ROUND(INDEX('Curva Mestra'!$C$20:$C$94,MATCH(E13,'Curva Mestra'!$A$20:$A$94,0)),0) | H13: =ROUND(G13*$B$4,0) | I13: =ROUND(G13*$B$5,0) | J13: Ruínas Élficas (Ecoril) — comércio com ruínas élficas ou saque de elite específico | K13: Dobrado, nao martelado. Os elfos nunca explicaram a diferenca a ninguem de fora. | L13: Ignora 2 pontos de Defesa de inimigos com armadura pesada.
A14: 6 | B14: Mecanismo Anao | C14: 26 | D14: 30 | E14: =ROUND((C14+D14)/2,0) | F14: #C08A3E | G14: =ROUND(INDEX('Curva Mestra'!$C$20:$C$94,MATCH(E14,'Curva Mestra'!$A$20:$A$94,0)),0) | H14: =ROUND(G14*$B$4,0) | I14: =ROUND(G14*$B$5,0) | J14: Câmara Mecânica Anã (Ecoril) — dungeon anã com puzzle mecânico | K14: Engrenagem sobre engrenagem - os anoes pararam de contar quantas pecas um machado precisa. | L14: 1x por combate, repete um ataque que errou.
A15: 7 | B15: Vidro Vulcanico | C15: 31 | D15: 35 | E15: =ROUND((C15+D15)/2,0) | F15: #4FA89B | G15: =ROUND(INDEX('Curva Mestra'!$C$20:$C$94,MATCH(E15,'Curva Mestra'!$A$20:$A$94,0)),0) | H15: =ROUND(G15*$B$4,0) | I15: =ROUND(G15*$B$5,0) | J15: Fenda Vulcânica Ativa (Rocha Alta) — mineral raro perto de fendas vulcânicas ativas | K15: Formado onde a rocha derretida encontrou o ar frio demais rapido demais. Corta como promessa quebrada. | L15: Ataques tem 10% de chance de causar Queimadura (2 de dano/turno por 2 turnos).
A16: 8 | B16: Ferro Orquico | C16: 36 | D16: 40 | E16: =ROUND((C16+D16)/2,0) | F16: #4B5320 | G16: =ROUND(INDEX('Curva Mestra'!$C$20:$C$94,MATCH(E16,'Curva Mestra'!$A$20:$A$94,0)),0) | H16: =ROUND(G16*$B$4,0) | I16: =ROUND(G16*$B$5,0) | J16: Acampamento Orc (Rocha Alta) — só dropa do chefe do bando (não se compra/mina) | K16: Nao se mina - se toma. Cada peca ja teve dono antes de ser sua. | L16: +2 de dano contra alvos Elite ou Boss.
A17: 9 | B17: Mithril | C17: 41 | D17: 45 | E17: =ROUND((C17+D17)/2,0) | F17: #6FA8DC | G17: =ROUND(INDEX('Curva Mestra'!$C$20:$C$94,MATCH(E17,'Curva Mestra'!$A$20:$A$94,0)),0) | H17: =ROUND(G17*$B$4,0) | I17: =ROUND(G17*$B$5,0) | J17: Cavernas Profundas de Mithril (Abismar) — guardadas por elemental | K17: Leve como se nao devesse existir. Ninguem sabe dizer se e metal ou memoria de metal. | L17: Reduz em 1 o custo de Mana de habilidades, se equipado por um conjurador.
A18: 10 | B18: Ebano | C18: 46 | D18: 50 | E18: =ROUND((C18+D18)/2,0) | F18: #2E2A3D | G18: =ROUND(INDEX('Curva Mestra'!$C$20:$C$94,MATCH(E18,'Curva Mestra'!$A$20:$A$94,0)),0) | H18: =ROUND(G18*$B$4,0) | I18: =ROUND(G18*$B$5,0) | J18: Fenda Vulcânica Morta (Abismar) | K18: Do outro lado da mesma fenda que deu o vidro - so que fria, morta, silenciosa. | L18: Ataques a noite ou no escuro causam +15% de dano.
A19: 11 | B19: Adamantina | C19: 51 | D19: 56 | E19: =ROUND((C19+D19)/2,0) | F19: #6E0E23 | G19: =ROUND(INDEX('Curva Mestra'!$C$20:$C$94,MATCH(E19,'Curva Mestra'!$A$20:$A$94,0)),0) | H19: =ROUND(G19*$B$4,0) | I19: =ROUND(G19*$B$5,0) | J19: Covil do Titã (Alto Bastião) — só dropa de bosses de tier | K19: Nao se encontra. Se herda de quem perdeu a luta pra guardar. | L19: Ignora a primeira reducao de dano por Defesa em cada combate.
A20: 12 | B20: Osso de Dragao | C20: 57 | D20: 62 | E20: =ROUND((C20+D20)/2,0) | F20: #E8DCC4 | G20: =ROUND(INDEX('Curva Mestra'!$C$20:$C$94,MATCH(E20,'Curva Mestra'!$A$20:$A$94,0)),0) | H20: =ROUND(G20*$B$4,0) | I20: =ROUND(G20*$B$5,0) | J20: Covil do Dragão Ancião (Alto Bastião) — exige abater um dragão | K20: Ainda quente ao toque, anos depois da ultima respiracao do dono. | L20: +3 de dano contra Dragoes e criaturas Cosmicas.
... A22: 14 | B22: Estelar / Cosmico | C22: 70 | D22: 75 | E22: =ROUND((C22+D22)/2,0) | F22: #8E44AD | G22: =ROUND(INDEX('Curva Mestra'!$C$20:$C$94,MATCH(E22,'Curva Mestra'!$A$20:$A$94,0)),0) | H22: =ROUND(G22*$B$4,0) | I22: =ROUND(G22*$B$5,0) | J22: Portal Estelar (O Limiar) — só loot de entidades | K22: Nao veio deste mundo, e talvez esteja tentando voltar pra casa atraves de voce. | L22: Ignora completamente a Defesa do alvo, uma vez por combate.

Sheet Como Usar
A1: Como Usar Esta Planilha
A3: 1. Curva Mestra - e o motor de tudo. Define quanto HP um personagem/monstro tem em
A4: cada nivel, e qual o dano de arma padrao esperado. Se algo parecer fraco ou forte
A5: demais durante o jogo real, ajuste os parametros em azul no topo dessa aba - todos
A6: os 75 niveis recalculam sozinhos.
A8: 2. Tiers - cada um dos 14 tiers de equipamento busca automaticamente o dano correspondente
A9: ao seu nivel medio na Curva Mestra. Raro e Lendario sao multiplicadores sobre o dano
A10: comum (ajustaveis em B4 e B5 no topo da aba Tiers).
A12: 3. Cores - a coluna Cor (hex) ja esta pintada com a cor real de cada tier. Use esse
A13: hex direto no design das cartas/HUD dos itens.
A15: 4. Convencao de cores do texto:
A16: - Azul = numero que voce pode/deve ajustar (parametro)
... A23: seu amigo chegar.

Sheet Armas
A1: Catalogo Completo de Armas
A2: Dano puxado automaticamente da aba Tiers. Ajuste os modificadores em azul abaixo.
A4: Tipo de Arma | B4: Multiplicador | C4: Ataques por Turno | D4: Nota | E4: Pode 2 Maos? | F4: Bonus Dano (2 maos)
A5: Adaga | B5: 0.8 | C5: 1 | D5: Ver Regras e Fórmulas Seção 8: 25% chance de golpe extra a 50% do dano ao acertar (não é multiplicação fixa) | E5: Nao | F5: 1
A6: Espada | B6: 1 | C6: 1 | D6: Equilibrada - referencia do sistema | E6: Sim (opcional) | F6: 1.2
A7: Machado | B7: 1.2 | C7: 1 | D7: Maior dano bruto do sistema — sem penalidade de ataque | E7: Sim (opcional) | F7: 1.25
A8: Maca | B8: 1.1 | C8: 1 | D8: Impacto/controle — afinidade com Ignora Defesa só em Variações específicas com esse efeito | E8: Sim (opcional) | F8: 1.2
A9: Arco | B9: 0.9 | C9: 1 | D9: Ataca a distancia, seguranca | E9: Sempre (obrigatorio) | F9: 1
A10: Manopla | B10: 0.85 | C10: 1 | D10: Sem golpe adicional — identidade é Atordoamento (20% de chance ao acertar) | E10: Nao | F10: 1
A11: Cetro | B11: 0.7 | C11: 1 | D11: Soma no dano magico, se houver magia no sistema | E11: Nao | F11: 1
A14: Tier | B14: Tipo | C14: Variação (nome completo) | D14: Efeito Especial | E14: Lore | F14: Dano Base Comum | G14: Dano Base Raro | H14: Mod. Tipo | I14: Dano Comum | J14: Dano Raro | K14: Mod. Variação | L14: Preço Venda Comum | M14: Preço Venda Raro
A15: Sucata Enferrujada | B15: Espada | C15: Espada de Sucata Enferrujada | E15: Lâmina de sucata amarrada com arame — corta, mas reclama a cada golpe. | F15: =INDEX(Tiers!$G$9:$G$22,MATCH($A15,Tiers!$B$9:$B$22,0)) | G15: =INDEX(Tiers!$H$9:$H$22,MATCH($A15,Tiers!$B$9:$B$22,0)) | H15: =INDEX($B$5:$B$11,MATCH($B15,$A$5:$A$11,0)) | I15: =ROUND(F15*H15*K15,0) | J15: =ROUND(G15*H15*K15,0) | K15: 1 | L15: =ROUND(I15*8,0) | M15: =ROUND(J15*10,0)
A16: Sucata Enferrujada | B16: Espada | C16: Espada Trincada | E16: Rachada perto do cabo; ainda serve, ninguém sabe até quando. | F16: =INDEX(Tiers!$G$9:$G$22,MATCH($A16,Tiers!$B$9:$B$22,0)) | G16: =INDEX(Tiers!$H$9:$H$22,MATCH($A16,Tiers!$B$9:$B$22,0)) | H16: =INDEX($B$5:$B$11,MATCH($B16,$A$5:$A$11,0)) | I16: =ROUND(F16*H16*K16,0) | J16: =ROUND(G16*H16*K16,0) | K16: 1 | L16: =ROUND(I16*8,0) | M16: =ROUND(J16*10,0)
A17: Sucata Enferrujada | B17: Espada | C17: Espada Serrilhada | D17: Sangramento | E17: Dentes de serra improvisados — não corta limpo, mas não deixa esquecer. | F17: =INDEX(Tiers!$G$9:$G$22,MATCH($A17,Tiers!$B$9:$B$22,0)) | G17: =INDEX(Tiers!$H$9:$H$22,MATCH($A17,Tiers!$B$9:$B$22,0)) | H17: =INDEX($B$5:$B$11,MATCH($B17,$A$5:$A$11,0)) | I17: =ROUND(F17*H17*K17,0) | J17: =ROUND(G17*H17*K17,0) | K17: 0.95 | L17: =ROUND(I17*8,0) | M17: =ROUND(J17*10,0)
A18: Sucata Enferrujada | B18: Espada | C18: Espada de Poda Afiada | E18: Ferramenta de colheita virada arma — mata com o que sobrou da lavoura. | F18: =INDEX(Tiers!$G$9:$G$22,MATCH($A18,Tiers!$B$9:$B$22,0)) | G18: =INDEX(Tiers!$H$9:$H$22,MATCH($A18,Tiers!$B$9:$B$22,0)) | H18: =INDEX($B$5:$B$11,MATCH($B18,$A$5:$A$11,0)) | I18: =ROUND(F18*H18*K18,0) | J18: =ROUND(G18*H18*K18,0) | K18: 1 | L18: =ROUND(I18*8,0) | M18: =ROUND(J18*10,0)
A19: Sucata Enferrujada | B19: Machado | C19: Machado de Sucata | E19: Cabeça de metal retorcido presa num cabo qualquer — pesa o bastante pra doer. | F19: =INDEX(Tiers!$G$9:$G$22,MATCH($A19,Tiers!$B$9:$B$22,0)) | G19: =INDEX(Tiers!$H$9:$H$22,MATCH($A19,Tiers!$B$9:$B$22,0)) | H19: =INDEX($B$5:$B$11,MATCH($B19,$A$5:$A$11,0)) | I19: =ROUND(F19*H19*K19,0) | J19: =ROUND(G19*H19*K19,0) | K19: 1 | L19: =ROUND(I19*8,0) | M19: =ROUND(J19*10,0)
A20: Sucata Enferrujada | B20: Machado | C20: Machado Cego | D20: Ignora Defesa | E20: Já não corta, só esmaga — e isso já basta. | F20: =INDEX(Tiers!$G$9:$G$22,MATCH($A20,Tiers!$B$9:$B$22,0)) | G20: =INDEX(Tiers!$H$9:$H$22,MATCH($A20,Tiers!$B$9:$B$22,0)) | H20: =INDEX($B$5:$B$11,MATCH($B20,$A$5:$A$11,0)) | I20: =ROUND(F20*H20*K20,0) | J20: =ROUND(G20*H20*K20,0) | K20: 0.96 | L20: =ROUND(I20*8,0) | M20: =ROUND(J20*10,0)
A21: Sucata Enferrujada | B21: Machado | C21: Machado de Lenhador Reforçado | E21: Feito pra árvore, adaptado pra carne. | F21: =INDEX(Tiers!$G$9:$G$22,MATCH($A21,Tiers!$B$9:$B$22,0)) | G21: =INDEX(Tiers!$H$9:$H$22,MATCH($A21,Tiers!$B$9:$B$22,0)) | H21: =INDEX($B$5:$B$11,MATCH($B21,$A$5:$A$11,0)) | I21: =ROUND(F21*H21*K21,0) | J21: =ROUND(G21*H21*K21,0) | K21: 1.05 | L21: =ROUND(I21*8,0) | M21: =ROUND(J21*10,0)
A22: Sucata Enferrujada | B22: Machado | C22: Machado Duplo Improvisado | E22: Duas lâminas de sucata soldadas — desequilibrado, mas assusta. | F22: =INDEX(Tiers!$G$9:$G$22,MATCH($A22,Tiers!$B$9:$B$22,0)) | G22: =INDEX(Tiers!$H$9:$H$22,MATCH($A22,Tiers!$B$9:$B$22,0)) | H22: =INDEX($B$5:$B$11,MATCH($B22,$A$5:$A$11,0)) | I22: =ROUND(F22*H22*K22,0) | J22: =ROUND(G22*H22*K22,0) | K22: 1.05 | L22: =ROUND(I22*8,0) | M22: =ROUND(J22*10,0)
A23: Sucata Enferrujada | B23: Arco | C23: Arco de Sucata | E23: Vergas de metal fino dobradas até quase quebrar. | F23: =INDEX(Tiers!$G$9:$G$22,MATCH($A23,Tiers!$B$9:$B$22,0)) | G23: =INDEX(Tiers!$H$9:$H$22,MATCH($A23,Tiers!$B$9:$B$22,0)) | H23: =INDEX($B$5:$B$11,MATCH($B23,$A$5:$A$11,0)) | I23: =ROUND(F23*H23*K23,0) | J23: =ROUND(G23*H23*K23,0) | K23: 1 | L23: =ROUND(I23*8,0) | M23: =ROUND(J23*10,0)
A24: Sucata Enferrujada | B24: Arco | C24: Arco de Corda Puída | E24: A corda já rompeu duas vezes — sempre foi remendada a tempo. | F24: =INDEX(Tiers!$G$9:$G$22,MATCH($A24,Tiers!$B$9:$B$22,0)) | G24: =INDEX(Tiers!$H$9:$H$22,MATCH($A24,Tiers!$B$9:$B$22,0)) | H24: =INDEX($B$5:$B$11,MATCH($B24,$A$5:$A$11,0)) | I24: =ROUND(F24*H24*K24,0) | J24: =ROUND(G24*H24*K24,0) | K24: 1 | L24: =ROUND(I24*8,0) | M24: =ROUND(J24*10,0)
A25: Sucata Enferrujada | B25: Arco | C25: Arco Caçador de Javali | E25: Talhado pra caçar o que ronda a vila. | F25: =INDEX(Tiers!$G$9:$G$22,MATCH($A25,Tiers!$B$9:$B$22,0)) | G25: =INDEX(Tiers!$H$9:$H$22,MATCH($A25,Tiers!$B$9:$B$22,0)) | H25: =INDEX($B$5:$B$11,MATCH($B25,$A$5:$A$11,0)) | I25: =ROUND(F25*H25*K25,0) | J25: =ROUND(G25*H25*K25,0) | K25: 1 | L25: =ROUND(I25*8,0) | M25: =ROUND(J25*10,0)
A26: Sucata Enferrujada | B26: Arco | C26: Arco Torto | E26: Não atira reto, mas quem usa há tempo já aprendeu a mirar torto também. | F26: =INDEX(Tiers!$G$9:$G$22,MATCH($A26,Tiers!$B$9:$B$22,0)) | G26: =INDEX(Tiers!$H$9:$H$22,MATCH($A26,Tiers!$B$9:$B$22,0)) | H26: =INDEX($B$5:$B$11,MATCH($B26,$A$5:$A$11,0)) | I26: =ROUND(F26*H26*K26,0) | J26: =ROUND(G26*H26*K26,0) | K26: 1 | L26: =ROUND(I26*8,0) | M26: =ROUND(J26*10,0)
A27: Sucata Enferrujada | B27: Adaga | C27: Adaga de Sucata | E27: Pequena, feia, e afiada o bastante pra doer o suficiente. | F27: =INDEX(Tiers!$G$9:$G$22,MATCH($A27,Tiers!$B$9:$B$22,0)) | G27: =INDEX(Tiers!$H$9:$H$22,MATCH($A27,Tiers!$B$9:$B$22,0)) | H27: =INDEX($B$5:$B$11,MATCH($B27,$A$5:$A$11,0)) | I27: =ROUND(F27*H27*K27,0) | J27: =ROUND(G27*H27*K27,0) | K27: 1 | L27: =ROUND(I27*8,0) | M27: =ROUND(J27*10,0)
A28: Sucata Enferrujada | B28: Adaga | C28: Adaga de Cozinha Reaproveitada | E28: Servia pra cortar pão. Agora corta outra coisa. | F28: =INDEX(Tiers!$G$9:$G$22,MATCH($A28,Tiers!$B$9:$B$22,0)) | G28: =INDEX(Tiers!$H$9:$H$22,MATCH($A28,Tiers!$B$9:$B$22,0)) | H28: =INDEX($B$5:$B$11,MATCH($B28,$A$5:$A$11,0)) | I28: =ROUND(F28*H28*K28,0) | J28: =ROUND(G28*H28*K28,0) | K28: 1 | L28: =ROUND(I28*8,0) | M28: =ROUND(J28*10,0)
A29: Sucata Enferrujada | B29: Adaga | C29: Adaga Curva | E29: Boa pra cortar corda. Melhor ainda pra cortar tendão. | F29: =INDEX(Tiers!$G$9:$G$22,MATCH($A29,Tiers!$B$9:$B$22,0)) | G29: =INDEX(Tiers!$H$9:$H$22,MATCH($A29,Tiers!$B$9:$B$22,0)) | H29: =INDEX($B$5:$B$11,MATCH($B29,$A$5:$A$11,0)) | I29: =ROUND(F29*H29*K29,0) | J29: =ROUND(G29*H29*K29,0) | K29: 1 | L29: =ROUND(I29*8,0) | M29: =ROUND(J29*10,0)
A30: Sucata Enferrujada | B30: Maca | C30: Maça de Sucata | E30: Cabeça pesada, cabo curto — não erra por falta de força. | F30: =INDEX(Tiers!$G$9:$G$22,MATCH($A30,Tiers!$B$9:$B$22,0)) | G30: =INDEX(Tiers!$H$9:$H$22,MATCH($A30,Tiers!$B$9:$B$22,0)) | H30: =INDEX($B$5:$B$11,MATCH($B30,$A$5:$A$11,0)) | I30: =ROUND(F30*H30*K30,0) | J30: =ROUND(G30*H30*K30,0) | K30: 1 | L30: =ROUND(I30*8,0) | M30: =ROUND(J30*10,0)
A31: Sucata Enferrujada | B31: Maca | C31: Maça Cravejada | D31: Sangramento | E31: Pregos tortos saindo de todo lado — ninguém perguntou se doía fazer. | F31: =INDEX(Tiers!$G$9:$G$22,MATCH($A31,Tiers!$B$9:$B$22,0)) | G31: =INDEX(Tiers!$H$9:$H$22,MATCH($A31,Tiers!$B$9:$B$22,0)) | H31: =INDEX($B$5:$B$11,MATCH($B31,$A$5:$A$11,0)) | I31: =ROUND(F31*H31*K31,0) | J31: =ROUND(G31*H31*K31,0) | K31: 0.96 | L31: =ROUND(I31*8,0) | M31: =ROUND(J31*10,0)
A32: Sucata Enferrujada | B32: Maca | C32: Maça de Ferreiro Improvisada | E32: Era martelo de bigorna. Agora é a última coisa que alguém vê. | F32: =INDEX(Tiers!$G$9:$G$22,MATCH($A32,Tiers!$B$9:$B$22,0)) | G32: =INDEX(Tiers!$H$9:$H$22,MATCH($A32,Tiers!$B$9:$B$22,0)) | H32: =INDEX($B$5:$B$11,MATCH($B32,$A$5:$A$11,0)) | I32: =ROUND(F32*H32*K32,0) | J32: =ROUND(G32*H32*K32,0) | K32: 1 | L32: =ROUND(I32*8,0) | M32: =ROUND(J32*10,0)
A33: Sucata Enferrujada | B33: Manopla | C33: Manopla de Sucata | E33: Placas de metal amarradas nos nós dos dedos. | F33: =INDEX(Tiers!$G$9:$G$22,MATCH($A33,Tiers!$B$9:$B$22,0)) | G33: =INDEX(Tiers!$H$9:$H$22,MATCH($A33,Tiers!$B$9:$B$22,0)) | H33: =INDEX($B$5:$B$11,MATCH($B33,$A$5:$A$11,0)) | I33: =ROUND(F33*H33*K33,0) | J33: =ROUND(G33*H33*K33,0) | K33: 1 | L33: =ROUND(I33*8,0) | M33: =ROUND(J33*10,0)
A34: Sucata Enferrujada | B34: Manopla | C34: Manopla Cravada | E34: Pontas de prego viradas pra fora — aperto de mão que ninguém pede duas vezes. | F34: =INDEX(Tiers!$G$9:$G$22,MATCH($A34,Tiers!$B$9:$B$22,0)) | G34: =INDEX(Tiers!$H$9:$H$22,MATCH($A34,Tiers!$B$9:$B$22,0)) | H34: =INDEX($B$5:$B$11,MATCH($B34,$A$5:$A$11,0)) | I34: =ROUND(F34*H34*K34,0) | J34: =ROUND(G34*H34*K34,0) | K34: 1 | L34: =ROUND(I34*8,0) | M34: =ROUND(J34*10,0)
A35: Sucata Enferrujada | B35: Cetro | C35: Cetro de Sucata | E35: Vara de metal com um cristal quebrado preso na ponta. | F35: =INDEX(Tiers!$G$9:$G$22,MATCH($A35,Tiers!$B$9:$B$22,0)) | G35: =INDEX(Tiers!$H$9:$H$22,MATCH($A35,Tiers!$B$9:$B$22,0)) | H35: =INDEX($B$5:$B$11,MATCH($B35,$A$5:$A$11,0)) | I35: =ROUND(F35*H35*K35,0) | J35: =ROUND(G35*H35*K35,0) | K35: 1 | L35: =ROUND(I35*8,0) | M35: =ROUND(J35*10,0)
A36: Sucata Enferrujada | B36: Cetro | C36: Cetro Rachado | E36: O cristal tá trincado. Ainda assim, funciona. | F36: =INDEX(Tiers!$G$9:$G$22,MATCH($A36,Tiers!$B$9:$B$22,0)) | G36: =INDEX(Tiers!$H$9:$H$22,MATCH($A36,Tiers!$B$9:$B$22,0)) | H36: =INDEX($B$5:$B$11,MATCH($B36,$A$5:$A$11,0)) | I36: =ROUND(F36*H36*K36,0) | J36: =ROUND(G36*H36*K36,0) | K36: 1 | L36: =ROUND(I36*8,0) | M36: =ROUND(J36*10,0)
A37: Bronze | B37: Espada | C37: Espada de Bronze | E37: Fundida em molde de areia, ainda cheira a fumaça da forja. | F37: =INDEX(Tiers!$G$9:$G$22,MATCH($A37,Tiers!$B$9:$B$22,0)) | G37: =INDEX(Tiers!$H$9:$H$22,MATCH($A37,Tiers!$B$9:$B$22,0)) | H37: =INDEX($B$5:$B$11,MATCH($B37,$A$5:$A$11,0)) | I37: =ROUND(F37*H37*K37,0) | J37: =ROUND(G37*H37*K37,0) | K37: 1 | L37: =ROUND(I37*8,0) | M37: =ROUND(J37*10,0)
A38: Bronze | B38: Espada | C38: Espada da Guilda | E38: Gravada com o selo dos Picaretas Negros — paga o dobro em juros de sangue. | F38: =INDEX(Tiers!$G$9:$G$22,MATCH($A38,Tiers!$B$9:$B$22,0)) | G38: =INDEX(Tiers!$H$9:$H$22,MATCH($A38,Tiers!$B$9:$B$22,0)) | H38: =INDEX($B$5:$B$11,MATCH($B38,$A$5:$A$11,0)) | I38: =ROUND(F38*H38*K38,0) | J38: =ROUND(G38*H38*K38,0) | K38: 1 | L38: =ROUND(I38*8,0) | M38: =ROUND(J38*10,0)
A39: Bronze | B39: Espada | C39: Espada Presa em Correntes | E39: Vinha acorrentada num carregamento que nunca chegou ao destino. | F39: =INDEX(Tiers!$G$9:$G$22,MATCH($A39,Tiers!$B$9:$B$22,0)) | G39: =INDEX(Tiers!$H$9:$H$22,MATCH($A39,Tiers!$B$9:$B$22,0)) | H39: =INDEX($B$5:$B$11,MATCH($B39,$A$5:$A$11,0)) | I39: =ROUND(F39*H39*K39,0) | J39: =ROUND(G39*H39*K39,0) | K39: 1 | L39: =ROUND(I39*8,0) | M39: =ROUND(J39*10,0)
A40: Bronze | B40: Espada | C40: Espada de Fundição Rápida | E40: Esfriou rápido demais pra ficar boa — mas ficou afiada. | F40: =INDEX(Tiers!$G$9:$G$22,MATCH($A40,Tiers!$B$9:$B$22,0)) | G40: =INDEX(Tiers!$H$9:$H$22,MATCH($A40,Tiers!$B$9:$B$22,0)) | H40: =INDEX($B$5:$B$11,MATCH($B40,$A$5:$A$11,0)) | I40: =ROUND(F40*H40*K40,0) | J40: =ROUND(G40*H40*K40,0) | K40: 1 | L40: =ROUND(I40*8,0) | M40: =ROUND(J40*10,0)
A41: Bronze | B41: Machado | C41: Machado de Bronze | E41: Peso justo pra quebrar rocha ou crânio, sem preferência. | F41: =INDEX(Tiers!$G$9:$G$22,MATCH($A41,Tiers!$B$9:$B$22,0)) | G41: =INDEX(Tiers!$H$9:$H$22,MATCH($A41,Tiers!$B$9:$B$22,0)) | H41: =INDEX($B$5:$B$11,MATCH($B41,$A$5:$A$11,0)) | I41: =ROUND(F41*H41*K41,0) | J41: =ROUND(G41*H41*K41,0) | K41: 1 | L41: =ROUND(I41*8,0) | M41: =ROUND(J41*10,0)
A42: Bronze | B42: Machado | C42: Machado de Mineiro Adaptado | E42: Trocou pedra por carne no dia em que os túneis pararam de ser seguros. | F42: =INDEX(Tiers!$G$9:$G$22,MATCH($A42,Tiers!$B$9:$B$22,0)) | G42: =INDEX(Tiers!$H$9:$H$22,MATCH($A42,Tiers!$B$9:$B$22,0)) | H42: =INDEX($B$5:$B$11,MATCH($B42,$A$5:$A$11,0)) | I42: =ROUND(F42*H42*K42,0) | J42: =ROUND(G42*H42*K42,0) | K42: 1 | L42: =ROUND(I42*8,0) | M42: =ROUND(J42*10,0)
A43: Bronze | B43: Machado | C43: Machado com Cabo de Cobre | E43: O metal do cabo range a cada golpe, como se reclamasse do trabalho extra. | F43: =INDEX(Tiers!$G$9:$G$22,MATCH($A43,Tiers!$B$9:$B$22,0)) | G43: =INDEX(Tiers!$H$9:$H$22,MATCH($A43,Tiers!$B$9:$B$22,0)) | H43: =INDEX($B$5:$B$11,MATCH($B43,$A$5:$A$11,0)) | I43: =ROUND(F43*H43*K43,0) | J43: =ROUND(G43*H43*K43,0) | K43: 1 | L43: =ROUND(I43*8,0) | M43: =ROUND(J43*10,0)
...

Sheet Bestiario
A1: Bestiario Inicial
A2: HP/Dano/Defesa calculados pela Curva Mestra a partir do nivel. Troque nomes/nivel a vontade.
A4: Papel | B4: Multiplicador de Dano | C4: Bonus de Defesa | D4: Fator de XP | E4: Bonus Ataque Extra
A5: Comum | B5: 1 | C5: 0 | D5: 0.12 | E5: 0
A6: Elite | B6: 1.3 | C6: 2 | D6: 0.35 | E6: 2
A7: Boss | B7: 1.6 | C7: 4 | D7: 1 | E7: 4
A8: Cosmico | B8: 2.2 | C8: 5 | D8: 2.5 | E8: 6
A11: Tier | B11: Nome do Monstro | C11: Papel | D11: Nivel | E11: HP | F11: Dano | G11: Defesa | H11: Origem/Descricao | I11: Golpe Especial | J11: Efeito Mecânico | K11: Motivação / Ligação com a Infecção | L11: HP ★★ Médio | M11: Dano ★★ Médio | N11: Defesa ★★ Médio | O11: HP ★★★ Difícil | P11: Dano ★★★ Difícil | Q11: Defesa ★★★ Difícil | R11: Quests Relacionadas | S11: Bônus de Ataque | T11: Materiais Dropados | U11: Fraqueza (Knowledge 4-5) | V11: Estilo de Combate | W11: Condição de Spawn | X11: Fase 2 | Y11: Interação Ambiental | Z11: Reação à Facção | AA11: Loot Único
A12: Sucata Enferrujada | B12: Cão de Caça Sanguíneo | C12: Comum | D12: 1 | E12: =ROUND(INDEX('Curva Mestra'!$F$20:$F$94,MATCH(D12,'Curva Mestra'!$A$20:$A$94,0)),0) | F12: =ROUND(INDEX('Curva Mestra'!$C$20:$C$94,MATCH(D12,'Curva Mestra'!$A$20:$A$94,0))*INDEX($B$5:$B$8,MATCH(C12,$A$5:$A$8,0)),0) | G12: =ROUND(INDEX('Curva Mestra'!$D$20:$D$94,MATCH(D12,'Curva Mestra'!$A$20:$A$94,0))+INDEX($C$5:$C$8,MATCH(C12,$A$5:$A$8,0)),0) | H12: Ronda a regiao do tier Sucata Enferrujada | I12: Mordida Voraz | J12: Causa 1 de sangramento no próximo turno se acertar. | K12: Cão de guarda comum que lambeu sangue seco nas primeiras portas marcadas — agora rosna por instinto de caça, não fome. | L12: =IF(C12="Comum",ROUND(E12*1.3,0),"—") | M12: =IF(C12="Comum",ROUND(F12*1.15,0),"—") | N12: =IF(C12="Comum",G12+2,"—") | O12: =IF(C12="Comum",ROUND(E12*1.6,0),"—") | P12: =IF(C12="Comum",ROUND(F12*1.3,0),"—") | Q12: =IF(C12="Comum",G12+4,"—") | R12: Latidos na Neblina | S12: =ROUND(INDEX('Curva Mestra'!$D$20:$D$94,MATCH(D12,'Curva Mestra'!$A$20:$A$94,0))-IF(C12="Comum",9,IF(C12="Elite",6,IF(C12="Boss",4,3))),0) | T12: Ouro + Couro Áspero de Javali (chance rara) + Presa Sanguínea | U12: Sem fraqueza óbvia — precisa de Knowledge alto pra descobrir algo específico. | V12: DPS | W12: Bosque Sombrio
A13: Sucata Enferrujada | B13: Enxame de Moscas-Sangue | C13: Comum | D13: 1 | E13: =ROUND(INDEX('Curva Mestra'!$F$20:$F$94,MATCH(D13,'Curva Mestra'!$A$20:$A$94,0)),0) | F13: =ROUND(INDEX('Curva Mestra'!$C$20:$C$94,MATCH(D13,'Curva Mestra'!$A$20:$A$94,0))*INDEX($B$5:$B$8,MATCH(C13,$A$5:$A$8,0)),0) | G13: =ROUND(INDEX('Curva Mestra'!$D$20:$D$94,MATCH(D13,'Curva Mestra'!$A$20:$A$94,0))+INDEX($C$5:$C$8,MATCH(C13,$A$5:$A$8,0)),0) | H13: Ligado a Praga, região de Sucata Enferrujada. | I13: Sopro Nauseante | J13: Reduz o Bônus de Ataque do alvo em 1 no próximo turno. | K13: Insetos que se multiplicaram sobre as manchas de sangue seco nas primeiras casas marcadas — respiram a infecção antes de qualquer criatura maior. | L13: =IF(C13="Comum",ROUND(E13*1.3,0),"—") | M13: =IF(C13="Comum",ROUND(F13*1.15,0),"—") | N13: =IF(C13="Comum",G13+2,"—") | O13: =IF(C13="Comum",ROUND(E13*1.6,0),"—") | P13: =IF(C13="Comum",ROUND(F13*1.3,0),"—") | Q13: =IF(C13="Comum",G13+4,"—") | R13: O Enxame que Não Para de Crescer | S13: =ROUND(INDEX('Curva Mestra'!$D$20:$D$94,MATCH(D13,'Curva Mestra'!$A$20:$A$94,0))-IF(C13="Comum",9,IF(C13="Elite",6,IF(C13="Boss",4,3))),0) | T13: Ouro + Couro Áspero de Javali (chance rara) + Asa de Mosca-Sangue | U13: Sem fraqueza óbvia — precisa de Knowledge alto pra descobrir algo específico. | V13: DPS | W13: Bosque Sombrio
A14: Sucata Enferrujada | B14: Cão Rafado | C14: Comum | D14: 1 | E14: =ROUND(INDEX('Curva Mestra'!$F$20:$F$94,MATCH(D14,'Curva Mestra'!$A$20:$A$94,0)),0) | F14: =ROUND(INDEX('Curva Mestra'!$C$20:$C$94,MATCH(D14,'Curva Mestra'!$A$20:$A$94,0))*INDEX($B$5:$B$8,MATCH(C14,$A$5:$A$8,0)),0) | G14: =ROUND(INDEX('Curva Mestra'!$D$20:$D$94,MATCH(D14,'Curva Mestra'!$A$20:$A$94,0))+INDEX($C$5:$C$8,MATCH(C14,$A$5:$A$8,0)),0) | H14: Corre nos arredores da Estrada dos Bandidos, sempre à frente do bando principal. | I14: Ganido de Alerta | J14: Alerta: o próximo encontro no mesmo local vem com +1 monstro. | K14: Corre na frente do bando, marca presas pelo cheiro. | L14: =IF(C14="Comum",ROUND(E14*1.3,0),"—") | M14: =IF(C14="Comum",ROUND(F14*1.15,0),"—") | N14: =IF(C14="Comum",G14+2,"—") | O14: =IF(C14="Comum",ROUND(E14*1.6,0),"—") | P14: =IF(C14="Comum",ROUND(F14*1.3,0),"—") | Q14: =IF(C14="Comum",G14+4,"—") | S14: =ROUND(3+0.6*D14+IF(C14="Comum",0,IF(C14="Elite",2,IF(C14="Boss",4,6))),0) | T14: Couro Áspero de Javali + Canino Enferrujado | U14: Atordoamento | V14: Batedor | W14: Estrada dos Bandidos | X14: Foge a 30% de HP pra buscar reforço.
A15: Sucata Enferrujada | B15: Bandido Novato | C15: Comum | D15: 1 | E15: =ROUND(INDEX('Curva Mestra'!$F$20:$F$94,MATCH(D15,'Curva Mestra'!$A$20:$A$94,0)),0) | F15: =ROUND(INDEX('Curva Mestra'!$C$20:$C$94,MATCH(D15,'Curva Mestra'!$A$20:$A$94,0))*INDEX($B$5:$B$8,MATCH(C15,$A$5:$A$8,0)),0) | G15: =ROUND(INDEX('Curva Mestra'!$D$20:$D$94,MATCH(D15,'Curva Mestra'!$A$20:$A$94,0))+INDEX($C$5:$C$8,MATCH(C15,$A$5:$A$8,0)),0) | H15: Recruta recente do bando que assalta a Estrada dos Bandidos. | I15: Golpe Trêmulo | J15: 25% de chance de errar por conta própria (mão treme). | K15: Entrou no bando semana passada. Ainda não matou ninguém. | L15: =IF(C15="Comum",ROUND(E15*1.3,0),"—") | M15: =IF(C15="Comum",ROUND(F15*1.15,0),"—") | N15: =IF(C15="Comum",G15+2,"—") | O15: =IF(C15="Comum",ROUND(E15*1.6,0),"—") | P15: =IF(C15="Comum",ROUND(F15*1.3,0),"—") | Q15: =IF(C15="Comum",G15+4,"—") | S15: =ROUND(3+0.6*D15+IF(C15="Comum",0,IF(C15="Elite",2,IF(C15="Boss",4,6))),0) | T15: Sucata Retorcida + Faca Cega de Recruta + Pano Ensanguentado | U15: Atordoamento | V15: DPS fraco | W15: Estrada dos Bandidos | Y15: Rende-se a 25% de HP — pode ser poupado (gancho de quest). | Z15: Milícia dos Desamparados aceita entregá-lo vivo em troca de reputação.
A16: Sucata Enferrujada | B16: Criança Marcada | C16: Comum | D16: 1 | E16: =ROUND(INDEX('Curva Mestra'!$F$20:$F$94,MATCH(D16,'Curva Mestra'!$A$20:$A$94,0)),0) | F16: =ROUND(INDEX('Curva Mestra'!$C$20:$C$94,MATCH(D16,'Curva Mestra'!$A$20:$A$94,0))*INDEX($B$5:$B$8,MATCH(C16,$A$5:$A$8,0)),0) | G16: =ROUND(INDEX('Curva Mestra'!$D$20:$D$94,MATCH(D16,'Curva Mestra'!$A$20:$A$94,0))+INDEX($C$5:$C$8,MATCH(C16,$A$5:$A$8,0)),0) | H16: Encontrada perdida no Acampamento dos Marcados. | I16: (não ataca) | J16: Não-hostil: só ataca se atacada primeiro. Se poupada, revela um local secreto. | K16: Não entende o que aconteceu com ela. Ainda procura a mãe. | L16: =IF(C16="Comum",ROUND(E16*1.3,0),"—") | M16: =IF(C16="Comum",ROUND(F16*1.15,0),"—") | N16: =IF(C16="Comum",G16+2,"—") | O16: =IF(C16="Comum",ROUND(E16*1.6,0),"—") | P16: =IF(C16="Comum",ROUND(F16*1.3,0),"—") | Q16: =IF(C16="Comum",G16+4,"—") | S16: =ROUND(3+0.6*D16+IF(C16="Comum",0,IF(C16="Elite",2,IF(C16="Boss",4,6))),0) | T16: Ouro + Boneco de Pano Remendado | U16: Sem fraqueza óbvia — precisa de Knowledge alto pra descobrir algo específico. | V16: Não-hostil | W16: Acampamento dos Marcados | Y16: Segue o jogador em silêncio por 2 explorações se poupada.
A17: Sucata Enferrujada | B17: Acólito Recém-Marcado | C17: Comum | D17: 1 | E17: =ROUND(INDEX('Curva Mestra'!$F$20:$F$94,MATCH(D17,'Curva Mestra'!$A$20:$A$94,0)),0) | F17: =ROUND(INDEX('Curva Mestra'!$C$20:$C$94,MATCH(D17,'Curva Mestra'!$A$20:$A$94,0))*INDEX($B$5:$B$8,MATCH(C17,$A$5:$A$8,0)),0) | G17: =ROUND(INDEX('Curva Mestra'!$D$20:$D$94,MATCH(D17,'Curva Mestra'!$A$20:$A$94,0))+INDEX($C$5:$C$8,MATCH(C17,$A$5:$A$8,0)),0) | H17: Novo membro do culto, ainda no Acampamento dos Marcados. | I17: Corte Hesitante | J17: Nenhum efeito adicional. | K17: Marcou a própria porta ontem. Ainda tem a mão tremendo. | L17: =IF(C17="Comum",ROUND(E17*1.3,0),"—") | M17: =IF(C17="Comum",ROUND(F17*1.15,0),"—") | N17: =IF(C17="Comum",G17+2,"—") | O17: =IF(C17="Comum",ROUND(E17*1.6,0),"—") | P17: =IF(C17="Comum",ROUND(F17*1.3,0),"—") | Q17: =IF(C17="Comum",G17+4,"—") | S17: =ROUND(3+0.6*D17+IF(C17="Comum",0,IF(C17="Elite",2,IF(C17="Boss",4,6))),0) | T17: Ouro + Fragmento de Tinta Ritual + Pano do Culto Rasgado | U17: Ignora Defesa | V17: DPS fraco | W17: Acampamento dos Marcados
A18: Sucata Enferrujada | B18: Leitão Marcado | C18: Comum | D18: 1 | E18: =ROUND(INDEX('Curva Mestra'!$F$20:$F$94,MATCH(D18,'Curva Mestra'!$A$20:$A$94,0)),0) | F18: =ROUND(INDEX('Curva Mestra'!$C$20:$C$94,MATCH(D18,'Curva Mestra'!$A$20:$A$94,0))*INDEX($B$5:$B$8,MATCH(C18,$A$5:$A$8,0)),0) | G18: =ROUND(INDEX('Curva Mestra'!$D$20:$D$94,MATCH(D18,'Curva Mestra'!$A$20:$A$94,0))+INDEX($C$5:$C$8,MATCH(C18,$A$5:$A$8,0)),0) | H18: Filhote do Javali Alfa, encontrado no Bosque Sombrio. | I18: Mordidinha | J18: Nenhum efeito adicional — sempre aparecem em grupo de 3. | K18: Ninhada do Javali Alfa. Já nasceram com a marca. | L18: =IF(C18="Comum",ROUND(E18*1.3,0),"—") | M18: =IF(C18="Comum",ROUND(F18*1.15,0),"—") | N18: =IF(C18="Comum",G18+2,"—") | O18: =IF(C18="Comum",ROUND(E18*1.6,0),"—") | P18: =IF(C18="Comum",ROUND(F18*1.3,0),"—") | Q18: =IF(C18="Comum",G18+4,"—") | S18: =ROUND(3+0.6*D18+IF(C18="Comum",0,IF(C18="Elite",2,IF(C18="Boss",4,6))),0) | T18: Ouro + Presa de Leitão + Couro Marcado de Leitão | U18: Queimadura | V18: Enxame | W18: Bosque Sombrio | Y18: Chamam o Javali Alfa se todos morrerem (10% de chance).
A19: Sucata Enferrujada | B19: Carrapato Grande do Javali | C19: Comum | D19: 1 | E19: =ROUND(INDEX('Curva Mestra'!$F$20:$F$94,MATCH(D19,'Curva Mestra'!$A$20:$A$94,0)),0) | F19: =ROUND(INDEX('Curva Mestra'!$C$20:$C$94,MATCH(D19,'Curva Mestra'!$A$20:$A$94,0))*INDEX($B$5:$B$8,MATCH(C19,$A$5:$A$8,0)),0) | G19: =ROUND(INDEX('Curva Mestra'!$D$20:$D$94,MATCH(D19,'Curva Mestra'!$A$20:$A$94,0))+INDEX($C$5:$C$8,MATCH(C19,$A$5:$A$8,0)),0) | H19: Vive grudado no Javali Selvagem Alfa ou em seus filhotes. | I19: Fixar | J19: Rouba Vida (15%) — só aparece junto com Javali Alfa ou Leitão. | K19: Vive no lombo dos javalis marcados, bebe o sangue infectado. | L19: =IF(C19="Comum",ROUND(E19*1.3,0),"—") | M19: =IF(C19="Comum",ROUND(F19*1.15,0),"—") | N19: =IF(C19="Comum",G19+2,"—") | O19: =IF(C19="Comum",ROUND(E19*1.6,0),"—") | P19: =IF(C19="Comum",ROUND(F19*1.3,0),"—") | Q19: =IF(C19="Comum",G19+4,"—") | S19: =ROUND(3+0.6*D19+IF(C19="Comum",0,IF(C19="Elite",2,IF(C19="Boss",4,6))),0) | T19: Ouro + Glândula de Carrapato | U19: Queimadura | V19: Parasita | W19: Bosque Sombrio, só com Javali/Leitão presente | Y19: Se o hospedeiro morrer, fica 2x mais agressivo.
A20: Sucata Enferrujada | B20: Bandido de Estrada Marcado | C20: Comum | D20: 2 | E20: =ROUND(INDEX('Curva Mestra'!$F$20:$F$94,MATCH(D20,'Curva Mestra'!$A$20:$A$94,0)),0) | F20: =ROUND(INDEX('Curva Mestra'!$C$20:$C$94,MATCH(D20,'Curva Mestra'!$A$20:$A$94,0))*INDEX($B$5:$B$8,MATCH(C20,$A$5:$A$8,0)),0) | G20: =ROUND(INDEX('Curva Mestra'!$D$20:$D$94,MATCH(D20,'Curva Mestra'!$A$20:$A$94,0))+INDEX($C$5:$C$8,MATCH(C20,$A$5:$A$8,0)),0) | H20: Ronda a regiao do tier Sucata Enferrujada | I20: Faca Enferrujada | J20: Nada especial — ameaça pela quantidade, não pela força. | K20: Bandido comum que achou um caco do "Fragmento do Sangue" perdido na estrada e o carrega como amuleto de sorte, sem saber o que é. | L20: =IF(C20="Comum",ROUND(E20*1.3,0),"—") | M20: =IF(C20="Comum",ROUND(F20*1.15,0),"—") | N20: =IF(C20="Comum",G20+2,"—") | O20: =IF(C20="Comum",ROUND(E20*1.6,0),"—") | P20: =IF(C20="Comum",ROUND(F20*1.3,0),"—") | Q20: =IF(C20="Comum",G20+4,"—") | R20: A Estrada Insegura; O Baú do Salteador Afogado | S20: =ROUND(INDEX('Curva Mestra'!$D$20:$D$94,MATCH(D20,'Curva Mestra'!$A$20:$A$94,0))-IF(C20="Comum",9,IF(C20="Elite",6,IF(C20="Boss",4,3))),0) | T20: Ouro + Couro Áspero de Javali (chance rara) + Faca Enferrujada de Bandido | U20: Sem fraqueza óbvia — precisa de Knowledge alto pra descobrir algo específico. | V20: DPS | W20: Bosque Sombrio
A21: Sucata Enferrujada | B21: Peregrino Marcado | C21: Comum | D21: 2 | E21: =ROUND(INDEX('Curva Mestra'!$F$20:$F$94,MATCH(D21,'Curva Mestra'!$A$20:$A$94,0)),0) | F21: =ROUND(INDEX('Curva Mestra'!$C$20:$C$94,MATCH(D21,'Curva Mestra'!$A$20:$A$94,0))*INDEX($B$5:$B$8,MATCH(C21,$A$5:$A$8,0)),0) | G21: =ROUND(INDEX('Curva Mestra'!$D$20:$D$94,MATCH(D21,'Curva Mestra'!$A$20:$A$94,0))+INDEX($C$5:$C$8,MATCH(C21,$A$5:$A$8,0)),0) | H21: Ligado a Zumbi, região de Sucata Enferrujada. | I21: Abraço de Ferrugem | J21: Tenta imobilizar o alvo por 1 turno (teste FOR CD 10 pra escapar). | K21: Um camponês que tocou uma porta pintada com dedos ensanguentados por curiosidade. Ainda usa as roupas de viagem — só nunca chegou a lugar nenhum. | L21: =IF(C21="Comum",ROUND(E21*1.3,0),"—") | M21: =IF(C21="Comum",ROUND(F21*1.15,0),"—") | N21: =IF(C21="Comum",G21+2,"—") | O21: =IF(C21="Comum",ROUND(E21*1.6,0),"—") | P21: =IF(C21="Comum",ROUND(F21*1.3,0),"—") | Q21: =IF(C21="Comum",G21+4,"—") | R21: O Amigo que Sumiu | S21: =ROUND(INDEX('Curva Mestra'!$D$20:$D$94,MATCH(D21,'Curva Mestra'!$A$20:$A$94,0))-IF(C21="Comum",9,IF(C21="Elite",6,IF(C21="Boss",4,3))),0) | T21: Ouro + Couro Áspero de Javali (chance rara) + Manto Rasgado de Peregrino | U21: Sem fraqueza óbvia — precisa de Knowledge alto pra descobrir algo específico. | V21: Controle | W21: Bosque Sombrio
A22: Sucata Enferrujada | B22: Enxame de Vermes Pálidos | C22: Comum | D22: 2 | E22: =ROUND(INDEX('Curva Mestra'!$F$20:$F$94,MATCH(D22,'Curva Mestra'!$A$20:$A$94,0)),0) | F22: =ROUND(INDEX('Curva Mestra'!$C$20:$C$94,MATCH(D22,'Curva Mestra'!$A$20:$A$94,0))*INDEX($B$5:$B$8,MATCH(C22,$A$5:$A$8,0)),0) | G22: =ROUND(INDEX('Curva Mestra'!$D$20:$D$94,MATCH(D22,'Curva Mestra'!$A$20:$A$94,0))+INDEX($C$5:$C$8,MATCH(C22,$A$5:$A$8,0)),0) | H22: Infesta o Veio de Sucata, alimentando-se dos restos do minério. | I22: Mordida Ácida | J22: Veneno (1 dano/turno, 2 turnos). | K22: Vivem no minério enferrujado, comem o que sobra dos mineradores. | L22: =IF(C22="Comum",ROUND(E22*1.3,0),"—") | M22: =IF(C22="Comum",ROUND(F22*1.15,0),"—") | N22: =IF(C22="Comum",G22+2,"—") | O22: =IF(C22="Comum",ROUND(E22*1.6,0),"—") | P22: =IF(C22="Comum",ROUND(F22*1.3,0),"—") | Q22: =IF(C22="Comum",G22+4,"—") | S22: =ROUND(3+0.6*D22+IF(C22="Comum",0,IF(C22="Elite",2,IF(C22="Boss",4,6))),0) | T22: Sucata Retorcida + Casulo de Verme Pálido + Baba Corrosiva | U22: Queimadura | V22: Debuffer | W22: Veio de Sucata | Y22: Contamina o material coletado ali (perde 1 unidade).
